2021-12-29 15:31:06,471 - E:\work_place\recongnition\MainWindow.py[line:45] - ERROR: 连接失败
2021-12-29 15:33:51,221 - E:\work_place\recongnition\MainWindow.py[line:45] - ERROR: 连接失败
2021-12-29 15:33:56,022 - E:\work_place\recongnition\MainWindow.py[line:45] - ERROR: 连接失败
2021-12-29 15:39:03,503 - E:\work_place\recongnition\MainWindow.py[line:45] - ERROR: 连接失败
2021-12-29 15:45:18,318 - E:\work_place\recongnition\MainWindow.py[line:45] - ERROR: 连接失败
2021-12-29 15:47:17,918 - E:\work_place\recongnition\MainWindow.py[line:45] - ERROR: 连接失败
